<?xml version="1.0" encoding="UTF-8"?>
<!-- Generated by org.testng.reporters.JUnitReportReporter -->
<testsuite hostname="NACTS-081729" name="automationFramework.TestCases.ApiOamLinkSubsystemErrors2" tests="16" failures="0" timestamp="29 Sep 2016 18:43:52 GMT" time="2.235" errors="3">
  <testcase name="ApiExternalRefNbrBlank" time="0.031" classname="automationFramework.TestCases.ApiOamLinkSubsystemErrors2"/>
  <testcase name="ApiBalanceTransferLarge" time="1.735" classname="automationFramework.TestCases.ApiOamLinkSubsystemErrors2">
    <error type="java.lang.AssertionError" message="expected [true] but found [false]">
      <![CDATA[java.lang.AssertionError: expected [true] but found [false]
	at org.testng.Assert.fail(Assert.java:94)
	at org.testng.Assert.failNotEquals(Assert.java:494)
	at org.testng.Assert.assertTrue(Assert.java:42)
	at org.testng.Assert.assertTrue(Assert.java:52)
	at automationFramework.TestCases.ApiOamLinkSubsystemErrors2.sendApiRequest(ApiOamLinkSubsystemErrors2.java:176)
	at automationFramework.TestCases.ApiOamLinkSubsystemErrors2.ApiBalanceTransferLarge(ApiOamLinkSubsystemErrors2.java:140)
	at sun.reflect.NativeMethodAccessorImpl.invoke0(Native Method)
	at sun.reflect.NativeMethodAccessorImpl.invoke(Unknown Source)
	at sun.reflect.DelegatingMethodAccessorImpl.invoke(Unknown Source)
	at java.lang.reflect.Method.invoke(Unknown Source)
	at org.testng.internal.MethodInvocationHelper.invokeMethod(MethodInvocationHelper.java:80)
	at org.testng.internal.Invoker.invokeMethod(Invoker.java:714)
	at org.testng.internal.Invoker.invokeTestMethod(Invoker.java:901)
	at org.testng.internal.Invoker.invokeTestMethods(Invoker.java:1231)
	at org.testng.internal.TestMethodWorker.invokeTestMethods(TestMethodWorker.java:127)
	at org.testng.internal.TestMethodWorker.run(TestMethodWorker.java:111)
	at org.testng.TestRunner.privateRun(TestRunner.java:767)
	at org.testng.TestRunner.run(TestRunner.java:617)
	at org.testng.SuiteRunner.runTest(SuiteRunner.java:334)
	at org.testng.SuiteRunner.runSequentially(SuiteRunner.java:329)
	at org.testng.SuiteRunner.privateRun(SuiteRunner.java:291)
	at org.testng.SuiteRunner.run(SuiteRunner.java:240)
	at org.testng.SuiteRunnerWorker.runSuite(SuiteRunnerWorker.java:52)
	at org.testng.SuiteRunnerWorker.run(SuiteRunnerWorker.java:86)
	at org.testng.TestNG.runSuitesSequentially(TestNG.java:1198)
	at org.testng.TestNG.runSuitesLocally(TestNG.java:1123)
	at org.testng.TestNG.run(TestNG.java:1031)
	at org.testng.remote.AbstractRemoteTestNG.run(AbstractRemoteTestNG.java:126)
	at org.testng.remote.RemoteTestNG.initAndRun(RemoteTestNG.java:137)
	at org.testng.remote.RemoteTestNG.main(RemoteTestNG.java:58)
]]>
    </error>
  </testcase> <!-- ApiBalanceTransferLarge -->
  <testcase name="ApiErrorAccountBlank" time="0.035" classname="automationFramework.TestCases.ApiOamLinkSubsystemErrors2"/>
  <testcase name="ApiBalanceTransferSmall" time="0.046" classname="automationFramework.TestCases.ApiOamLinkSubsystemErrors2"/>
  <testcase name="ApiErrorCustomerIDBlank" time="0.029" classname="automationFramework.TestCases.ApiOamLinkSubsystemErrors2"/>
  <testcase name="ApiExternalSubsystemAccountIdMax" time="0.026" classname="automationFramework.TestCases.ApiOamLinkSubsystemErrors2"/>
  <testcase name="ApiErrorCustomerIDIncorrect" time="0.029" classname="automationFramework.TestCases.ApiOamLinkSubsystemErrors2"/>
  <testcase name="ApiErrorCustomerIDMax" time="0.029" classname="automationFramework.TestCases.ApiOamLinkSubsystemErrors2"/>
  <testcase name="ApiErrorClientRefIdMax" time="0.029" classname="automationFramework.TestCases.ApiOamLinkSubsystemErrors2"/>
  <testcase name="ApiNickNameMax" time="0.032" classname="automationFramework.TestCases.ApiOamLinkSubsystemErrors2"/>
  <testcase name="ApiErrorClientRefIdBlank" time="0.036" classname="automationFramework.TestCases.ApiOamLinkSubsystemErrors2"/>
  <testcase name="ApiExternalRefNbrMax" time="0.024" classname="automationFramework.TestCases.ApiOamLinkSubsystemErrors2"/>
  <testcase name="ApiErrorAccountMax" time="0.037" classname="automationFramework.TestCases.ApiOamLinkSubsystemErrors2">
    <error type="java.lang.AssertionError" message="expected [true] but found [false]">
      <![CDATA[java.lang.AssertionError: expected [true] but found [false]
	at org.testng.Assert.fail(Assert.java:94)
	at org.testng.Assert.failNotEquals(Assert.java:494)
	at org.testng.Assert.assertTrue(Assert.java:42)
	at org.testng.Assert.assertTrue(Assert.java:52)
	at automationFramework.TestCases.ApiOamLinkSubsystemErrors2.sendApiRequest(ApiOamLinkSubsystemErrors2.java:176)
	at automationFramework.TestCases.ApiOamLinkSubsystemErrors2.ApiErrorAccountMax(ApiOamLinkSubsystemErrors2.java:81)
	at sun.reflect.NativeMethodAccessorImpl.invoke0(Native Method)
	at sun.reflect.NativeMethodAccessorImpl.invoke(Unknown Source)
	at sun.reflect.DelegatingMethodAccessorImpl.invoke(Unknown Source)
	at java.lang.reflect.Method.invoke(Unknown Source)
	at org.testng.internal.MethodInvocationHelper.invokeMethod(MethodInvocationHelper.java:80)
	at org.testng.internal.Invoker.invokeMethod(Invoker.java:714)
	at org.testng.internal.Invoker.invokeTestMethod(Invoker.java:901)
	at org.testng.internal.Invoker.invokeTestMethods(Invoker.java:1231)
	at org.testng.internal.TestMethodWorker.invokeTestMethods(TestMethodWorker.java:127)
	at org.testng.internal.TestMethodWorker.run(TestMethodWorker.java:111)
	at org.testng.TestRunner.privateRun(TestRunner.java:767)
	at org.testng.TestRunner.run(TestRunner.java:617)
	at org.testng.SuiteRunner.runTest(SuiteRunner.java:334)
	at org.testng.SuiteRunner.runSequentially(SuiteRunner.java:329)
	at org.testng.SuiteRunner.privateRun(SuiteRunner.java:291)
	at org.testng.SuiteRunner.run(SuiteRunner.java:240)
	at org.testng.SuiteRunnerWorker.runSuite(SuiteRunnerWorker.java:52)
	at org.testng.SuiteRunnerWorker.run(SuiteRunnerWorker.java:86)
	at org.testng.TestNG.runSuitesSequentially(TestNG.java:1198)
	at org.testng.TestNG.runSuitesLocally(TestNG.java:1123)
	at org.testng.TestNG.run(TestNG.java:1031)
	at org.testng.remote.AbstractRemoteTestNG.run(AbstractRemoteTestNG.java:126)
	at org.testng.remote.RemoteTestNG.initAndRun(RemoteTestNG.java:137)
	at org.testng.remote.RemoteTestNG.main(RemoteTestNG.java:58)
]]>
    </error>
  </testcase> <!-- ApiErrorAccountMax -->
  <testcase name="ApiExternalSubsystemAccountIdBlank" time="0.032" classname="automationFramework.TestCases.ApiOamLinkSubsystemErrors2"/>
  <testcase name="ApiSubsystemIdMax" time="0.049" classname="automationFramework.TestCases.ApiOamLinkSubsystemErrors2">
    <error type="java.lang.AssertionError" message="expected [true] but found [false]">
      <![CDATA[java.lang.AssertionError: expected [true] but found [false]
	at org.testng.Assert.fail(Assert.java:94)
	at org.testng.Assert.failNotEquals(Assert.java:494)
	at org.testng.Assert.assertTrue(Assert.java:42)
	at org.testng.Assert.assertTrue(Assert.java:52)
	at automationFramework.TestCases.ApiOamLinkSubsystemErrors2.sendApiRequest(ApiOamLinkSubsystemErrors2.java:176)
	at automationFramework.TestCases.ApiOamLinkSubsystemErrors2.ApiSubsystemIdMax(ApiOamLinkSubsystemErrors2.java:115)
	at sun.reflect.NativeMethodAccessorImpl.invoke0(Native Method)
	at sun.reflect.NativeMethodAccessorImpl.invoke(Unknown Source)
	at sun.reflect.DelegatingMethodAccessorImpl.invoke(Unknown Source)
	at java.lang.reflect.Method.invoke(Unknown Source)
	at org.testng.internal.MethodInvocationHelper.invokeMethod(MethodInvocationHelper.java:80)
	at org.testng.internal.Invoker.invokeMethod(Invoker.java:714)
	at org.testng.internal.Invoker.invokeTestMethod(Invoker.java:901)
	at org.testng.internal.Invoker.invokeTestMethods(Invoker.java:1231)
	at org.testng.internal.TestMethodWorker.invokeTestMethods(TestMethodWorker.java:127)
	at org.testng.internal.TestMethodWorker.run(TestMethodWorker.java:111)
	at org.testng.TestRunner.privateRun(TestRunner.java:767)
	at org.testng.TestRunner.run(TestRunner.java:617)
	at org.testng.SuiteRunner.runTest(SuiteRunner.java:334)
	at org.testng.SuiteRunner.runSequentially(SuiteRunner.java:329)
	at org.testng.SuiteRunner.privateRun(SuiteRunner.java:291)
	at org.testng.SuiteRunner.run(SuiteRunner.java:240)
	at org.testng.SuiteRunnerWorker.runSuite(SuiteRunnerWorker.java:52)
	at org.testng.SuiteRunnerWorker.run(SuiteRunnerWorker.java:86)
	at org.testng.TestNG.runSuitesSequentially(TestNG.java:1198)
	at org.testng.TestNG.runSuitesLocally(TestNG.java:1123)
	at org.testng.TestNG.run(TestNG.java:1031)
	at org.testng.remote.AbstractRemoteTestNG.run(AbstractRemoteTestNG.java:126)
	at org.testng.remote.RemoteTestNG.initAndRun(RemoteTestNG.java:137)
	at org.testng.remote.RemoteTestNG.main(RemoteTestNG.java:58)
]]>
    </error>
  </testcase> <!-- ApiSubsystemIdMax -->
  <testcase name="ApiErrorAccountNotFound" time="0.036" classname="automationFramework.TestCases.ApiOamLinkSubsystemErrors2"/>
</testsuite> <!-- automationFramework.TestCases.ApiOamLinkSubsystemErrors2 -->
