<?xml version="1.0" encoding="UTF-8"?>
<!-- Generated by org.testng.reporters.JUnitReportReporter -->
<testsuite hostname="NACTS-081729" name="automationFramework.NextWave2RestApi.ApiCustomerPost" tests="72" failures="8" timestamp="29 Nov 2016 22:56:03 GMT" time="16.199" errors="12">
  <testcase name="apiErrorMaxLengthCity" time="0.134" classname="automationFramework.NextWave2RestApi.ApiCustomerPost"/>
  <testcase name="apiErrorMaxLengthPersonalId" time="0.115" classname="automationFramework.NextWave2RestApi.ApiCustomerPost"/>
  <testcase name="apiErrorBlankPhoneNumber3" time="0.228" classname="automationFramework.NextWave2RestApi.ApiCustomerPost">
    <error type="java.lang.AssertionError" message="expected [contact.phone[2].phoneNumber] but found [contact.phone[2].number]">
      <![CDATA[java.lang.AssertionError: expected [contact.phone[2].phoneNumber] but found [contact.phone[2].number]
	at org.testng.Assert.fail(Assert.java:94)
	at org.testng.Assert.failNotEquals(Assert.java:494)
	at org.testng.Assert.assertEquals(Assert.java:123)
	at org.testng.Assert.assertEquals(Assert.java:176)
	at org.testng.Assert.assertEquals(Assert.java:186)
	at automationFramework.NextWave2RestApi.ApiCustomerPost.checkError(ApiCustomerPost.java:1019)
	at automationFramework.NextWave2RestApi.ApiCustomerPost.apiErrorBlankPhoneNumber3(ApiCustomerPost.java:500)
	at sun.reflect.NativeMethodAccessorImpl.invoke0(Native Method)
	at sun.reflect.NativeMethodAccessorImpl.invoke(Unknown Source)
	at sun.reflect.DelegatingMethodAccessorImpl.invoke(Unknown Source)
	at java.lang.reflect.Method.invoke(Unknown Source)
	at org.testng.internal.MethodInvocationHelper.invokeMethod(MethodInvocationHelper.java:80)
	at org.testng.internal.Invoker.invokeMethod(Invoker.java:714)
	at org.testng.internal.Invoker.invokeTestMethod(Invoker.java:901)
	at org.testng.internal.Invoker.invokeTestMethods(Invoker.java:1231)
	at org.testng.internal.TestMethodWorker.invokeTestMethods(TestMethodWorker.java:127)
	at org.testng.internal.TestMethodWorker.run(TestMethodWorker.java:111)
	at org.testng.TestRunner.privateRun(TestRunner.java:767)
	at org.testng.TestRunner.run(TestRunner.java:617)
	at org.testng.SuiteRunner.runTest(SuiteRunner.java:334)
	at org.testng.SuiteRunner.runSequentially(SuiteRunner.java:329)
	at org.testng.SuiteRunner.privateRun(SuiteRunner.java:291)
	at org.testng.SuiteRunner.run(SuiteRunner.java:240)
	at org.testng.SuiteRunnerWorker.runSuite(SuiteRunnerWorker.java:52)
	at org.testng.SuiteRunnerWorker.run(SuiteRunnerWorker.java:86)
	at org.testng.TestNG.runSuitesSequentially(TestNG.java:1198)
	at org.testng.TestNG.runSuitesLocally(TestNG.java:1123)
	at org.testng.TestNG.run(TestNG.java:1031)
	at org.testng.remote.AbstractRemoteTestNG.run(AbstractRemoteTestNG.java:126)
	at org.testng.remote.RemoteTestNG.initAndRun(RemoteTestNG.java:137)
	at org.testng.remote.RemoteTestNG.main(RemoteTestNG.java:58)
]]>
    </error>
  </testcase> <!-- apiErrorBlankPhoneNumber3 -->
  <testcase name="apiErrorMaxLengthAddress2" time="0.124" classname="automationFramework.NextWave2RestApi.ApiCustomerPost"/>
  <testcase name="apiErrorBlankPhoneNumber" time="0.115" classname="automationFramework.NextWave2RestApi.ApiCustomerPost">
    <error type="java.lang.AssertionError" message="expected [contact.phone[0].phoneNumber] but found [contact.phone[0].number]">
      <![CDATA[java.lang.AssertionError: expected [contact.phone[0].phoneNumber] but found [contact.phone[0].number]
	at org.testng.Assert.fail(Assert.java:94)
	at org.testng.Assert.failNotEquals(Assert.java:494)
	at org.testng.Assert.assertEquals(Assert.java:123)
	at org.testng.Assert.assertEquals(Assert.java:176)
	at org.testng.Assert.assertEquals(Assert.java:186)
	at automationFramework.NextWave2RestApi.ApiCustomerPost.checkError(ApiCustomerPost.java:1019)
	at automationFramework.NextWave2RestApi.ApiCustomerPost.apiErrorBlankPhoneNumber(ApiCustomerPost.java:420)
	at sun.reflect.NativeMethodAccessorImpl.invoke0(Native Method)
	at sun.reflect.NativeMethodAccessorImpl.invoke(Unknown Source)
	at sun.reflect.DelegatingMethodAccessorImpl.invoke(Unknown Source)
	at java.lang.reflect.Method.invoke(Unknown Source)
	at org.testng.internal.MethodInvocationHelper.invokeMethod(MethodInvocationHelper.java:80)
	at org.testng.internal.Invoker.invokeMethod(Invoker.java:714)
	at org.testng.internal.Invoker.invokeTestMethod(Invoker.java:901)
	at org.testng.internal.Invoker.invokeTestMethods(Invoker.java:1231)
	at org.testng.internal.TestMethodWorker.invokeTestMethods(TestMethodWorker.java:127)
	at org.testng.internal.TestMethodWorker.run(TestMethodWorker.java:111)
	at org.testng.TestRunner.privateRun(TestRunner.java:767)
	at org.testng.TestRunner.run(TestRunner.java:617)
	at org.testng.SuiteRunner.runTest(SuiteRunner.java:334)
	at org.testng.SuiteRunner.runSequentially(SuiteRunner.java:329)
	at org.testng.SuiteRunner.privateRun(SuiteRunner.java:291)
	at org.testng.SuiteRunner.run(SuiteRunner.java:240)
	at org.testng.SuiteRunnerWorker.runSuite(SuiteRunnerWorker.java:52)
	at org.testng.SuiteRunnerWorker.run(SuiteRunnerWorker.java:86)
	at org.testng.TestNG.runSuitesSequentially(TestNG.java:1198)
	at org.testng.TestNG.runSuitesLocally(TestNG.java:1123)
	at org.testng.TestNG.run(TestNG.java:1031)
	at org.testng.remote.AbstractRemoteTestNG.run(AbstractRemoteTestNG.java:126)
	at org.testng.remote.RemoteTestNG.initAndRun(RemoteTestNG.java:137)
	at org.testng.remote.RemoteTestNG.main(RemoteTestNG.java:58)
]]>
    </error>
  </testcase> <!-- apiErrorBlankPhoneNumber -->
  <testcase name="apiErrorBlankContactLastName" time="0.135" classname="automationFramework.NextWave2RestApi.ApiCustomerPost"/>
  <testcase name="apiErrorBlankUserName" time="0.112" classname="automationFramework.NextWave2RestApi.ApiCustomerPost"/>
  <testcase name="apiErrorTooLongPin" time="0.134" classname="automationFramework.NextWave2RestApi.ApiCustomerPost"/>
  <testcase name="apiErrorInvalidPhoneType" time="0.135" classname="automationFramework.NextWave2RestApi.ApiCustomerPost">
    <error type="java.lang.AssertionError" message="expected [contact.phone[0].phoneType] but found [contact.phone[0].type]">
      <![CDATA[java.lang.AssertionError: expected [contact.phone[0].phoneType] but found [contact.phone[0].type]
	at org.testng.Assert.fail(Assert.java:94)
	at org.testng.Assert.failNotEquals(Assert.java:494)
	at org.testng.Assert.assertEquals(Assert.java:123)
	at org.testng.Assert.assertEquals(Assert.java:176)
	at org.testng.Assert.assertEquals(Assert.java:186)
	at automationFramework.NextWave2RestApi.ApiCustomerPost.checkError(ApiCustomerPost.java:1019)
	at automationFramework.NextWave2RestApi.ApiCustomerPost.apiErrorInvalidPhoneType(ApiCustomerPost.java:450)
	at sun.reflect.NativeMethodAccessorImpl.invoke0(Native Method)
	at sun.reflect.NativeMethodAccessorImpl.invoke(Unknown Source)
	at sun.reflect.DelegatingMethodAccessorImpl.invoke(Unknown Source)
	at java.lang.reflect.Method.invoke(Unknown Source)
	at org.testng.internal.MethodInvocationHelper.invokeMethod(MethodInvocationHelper.java:80)
	at org.testng.internal.Invoker.invokeMethod(Invoker.java:714)
	at org.testng.internal.Invoker.invokeTestMethod(Invoker.java:901)
	at org.testng.internal.Invoker.invokeTestMethods(Invoker.java:1231)
	at org.testng.internal.TestMethodWorker.invokeTestMethods(TestMethodWorker.java:127)
	at org.testng.internal.TestMethodWorker.run(TestMethodWorker.java:111)
	at org.testng.TestRunner.privateRun(TestRunner.java:767)
	at org.testng.TestRunner.run(TestRunner.java:617)
	at org.testng.SuiteRunner.runTest(SuiteRunner.java:334)
	at org.testng.SuiteRunner.runSequentially(SuiteRunner.java:329)
	at org.testng.SuiteRunner.privateRun(SuiteRunner.java:291)
	at org.testng.SuiteRunner.run(SuiteRunner.java:240)
	at org.testng.SuiteRunnerWorker.runSuite(SuiteRunnerWorker.java:52)
	at org.testng.SuiteRunnerWorker.run(SuiteRunnerWorker.java:86)
	at org.testng.TestNG.runSuitesSequentially(TestNG.java:1198)
	at org.testng.TestNG.runSuitesLocally(TestNG.java:1123)
	at org.testng.TestNG.run(TestNG.java:1031)
	at org.testng.remote.AbstractRemoteTestNG.run(AbstractRemoteTestNG.java:126)
	at org.testng.remote.RemoteTestNG.initAndRun(RemoteTestNG.java:137)
	at org.testng.remote.RemoteTestNG.main(RemoteTestNG.java:58)
]]>
    </error>
  </testcase> <!-- apiErrorInvalidPhoneType -->
  <testcase name="apiErrorInvalidPersonalIdType" time="0.124" classname="automationFramework.NextWave2RestApi.ApiCustomerPost"/>
  <testcase name="apiErrorInvalidUserName" time="0.198" classname="automationFramework.NextWave2RestApi.ApiCustomerPost"/>
  <testcase name="apiErrorBlankPhoneType3" time="0.133" classname="automationFramework.NextWave2RestApi.ApiCustomerPost">
    <error type="java.lang.AssertionError" message="expected [contact.phone[2].phoneType] but found [contact.phone[2].type]">
      <![CDATA[java.lang.AssertionError: expected [contact.phone[2].phoneType] but found [contact.phone[2].type]
	at org.testng.Assert.fail(Assert.java:94)
	at org.testng.Assert.failNotEquals(Assert.java:494)
	at org.testng.Assert.assertEquals(Assert.java:123)
	at org.testng.Assert.assertEquals(Assert.java:176)
	at org.testng.Assert.assertEquals(Assert.java:186)
	at automationFramework.NextWave2RestApi.ApiCustomerPost.checkError(ApiCustomerPost.java:1019)
	at automationFramework.NextWave2RestApi.ApiCustomerPost.apiErrorBlankPhoneType3(ApiCustomerPost.java:521)
	at sun.reflect.NativeMethodAccessorImpl.invoke0(Native Method)
	at sun.reflect.NativeMethodAccessorImpl.invoke(Unknown Source)
	at sun.reflect.DelegatingMethodAccessorImpl.invoke(Unknown Source)
	at java.lang.reflect.Method.invoke(Unknown Source)
	at org.testng.internal.MethodInvocationHelper.invokeMethod(MethodInvocationHelper.java:80)
	at org.testng.internal.Invoker.invokeMethod(Invoker.java:714)
	at org.testng.internal.Invoker.invokeTestMethod(Invoker.java:901)
	at org.testng.internal.Invoker.invokeTestMethods(Invoker.java:1231)
	at org.testng.internal.TestMethodWorker.invokeTestMethods(TestMethodWorker.java:127)
	at org.testng.internal.TestMethodWorker.run(TestMethodWorker.java:111)
	at org.testng.TestRunner.privateRun(TestRunner.java:767)
	at org.testng.TestRunner.run(TestRunner.java:617)
	at org.testng.SuiteRunner.runTest(SuiteRunner.java:334)
	at org.testng.SuiteRunner.runSequentially(SuiteRunner.java:329)
	at org.testng.SuiteRunner.privateRun(SuiteRunner.java:291)
	at org.testng.SuiteRunner.run(SuiteRunner.java:240)
	at org.testng.SuiteRunnerWorker.runSuite(SuiteRunnerWorker.java:52)
	at org.testng.SuiteRunnerWorker.run(SuiteRunnerWorker.java:86)
	at org.testng.TestNG.runSuitesSequentially(TestNG.java:1198)
	at org.testng.TestNG.runSuitesLocally(TestNG.java:1123)
	at org.testng.TestNG.run(TestNG.java:1031)
	at org.testng.remote.AbstractRemoteTestNG.run(AbstractRemoteTestNG.java:126)
	at org.testng.remote.RemoteTestNG.initAndRun(RemoteTestNG.java:137)
	at org.testng.remote.RemoteTestNG.main(RemoteTestNG.java:58)
]]>
    </error>
  </testcase> <!-- apiErrorBlankPhoneType3 -->
  <testcase name="apiErrorBlankPersonalIdType" time="0.148" classname="automationFramework.NextWave2RestApi.ApiCustomerPost"/>
  <testcase name="apiErrorContainConsecutiveCharacterPassword" time="1.339" classname="automationFramework.NextWave2RestApi.ApiCustomerPost"/>
  <testcase name="apiErrorContainUsernamePassword" time="0.136" classname="automationFramework.NextWave2RestApi.ApiCustomerPost"/>
  <testcase name="apiErrorContainContigousCharacterPin" time="0.156" classname="automationFramework.NextWave2RestApi.ApiCustomerPost">
    <failure type="java.lang.NullPointerException">
      <![CDATA[java.lang.NullPointerException
	at automationFramework.NextWave2RestApi.ApiCustomerPost.checkError(ApiCustomerPost.java:1019)
	at automationFramework.NextWave2RestApi.ApiCustomerPost.apiErrorContainContigousCharacterPin(ApiCustomerPost.java:804)
	at sun.reflect.NativeMethodAccessorImpl.invoke0(Native Method)
	at sun.reflect.NativeMethodAccessorImpl.invoke(Unknown Source)
	at sun.reflect.DelegatingMethodAccessorImpl.invoke(Unknown Source)
	at java.lang.reflect.Method.invoke(Unknown Source)
	at org.testng.internal.MethodInvocationHelper.invokeMethod(MethodInvocationHelper.java:80)
	at org.testng.internal.Invoker.invokeMethod(Invoker.java:714)
	at org.testng.internal.Invoker.invokeTestMethod(Invoker.java:901)
	at org.testng.internal.Invoker.invokeTestMethods(Invoker.java:1231)
	at org.testng.internal.TestMethodWorker.invokeTestMethods(TestMethodWorker.java:127)
	at org.testng.internal.TestMethodWorker.run(TestMethodWorker.java:111)
	at org.testng.TestRunner.privateRun(TestRunner.java:767)
	at org.testng.TestRunner.run(TestRunner.java:617)
	at org.testng.SuiteRunner.runTest(SuiteRunner.java:334)
	at org.testng.SuiteRunner.runSequentially(SuiteRunner.java:329)
	at org.testng.SuiteRunner.privateRun(SuiteRunner.java:291)
	at org.testng.SuiteRunner.run(SuiteRunner.java:240)
	at org.testng.SuiteRunnerWorker.runSuite(SuiteRunnerWorker.java:52)
	at org.testng.SuiteRunnerWorker.run(SuiteRunnerWorker.java:86)
	at org.testng.TestNG.runSuitesSequentially(TestNG.java:1198)
	at org.testng.TestNG.runSuitesLocally(TestNG.java:1123)
	at org.testng.TestNG.run(TestNG.java:1031)
	at org.testng.remote.AbstractRemoteTestNG.run(AbstractRemoteTestNG.java:126)
	at org.testng.remote.RemoteTestNG.initAndRun(RemoteTestNG.java:137)
	at org.testng.remote.RemoteTestNG.main(RemoteTestNG.java:58)
]]>
    </failure>
  </testcase> <!-- apiErrorContainContigousCharacterPin -->
  <testcase name="apiGetCustomerInfo" time="0.319" classname="automationFramework.NextWave2RestApi.ApiCustomerPost"/>
  <testcase name="apiErrorInvalidCustomerType" time="0.110" classname="automationFramework.NextWave2RestApi.ApiCustomerPost"/>
  <testcase name="apiErrorMixCasesPassword" time="0.155" classname="automationFramework.NextWave2RestApi.ApiCustomerPost">
    <failure type="java.lang.NullPointerException">
      <![CDATA[java.lang.NullPointerException
	at automationFramework.NextWave2RestApi.ApiCustomerPost.checkError(ApiCustomerPost.java:1019)
	at automationFramework.NextWave2RestApi.ApiCustomerPost.apiErrorMixCasesPassword(ApiCustomerPost.java:743)
	at sun.reflect.NativeMethodAccessorImpl.invoke0(Native Method)
	at sun.reflect.NativeMethodAccessorImpl.invoke(Unknown Source)
	at sun.reflect.DelegatingMethodAccessorImpl.invoke(Unknown Source)
	at java.lang.reflect.Method.invoke(Unknown Source)
	at org.testng.internal.MethodInvocationHelper.invokeMethod(MethodInvocationHelper.java:80)
	at org.testng.internal.Invoker.invokeMethod(Invoker.java:714)
	at org.testng.internal.Invoker.invokeTestMethod(Invoker.java:901)
	at org.testng.internal.Invoker.invokeTestMethods(Invoker.java:1231)
	at org.testng.internal.TestMethodWorker.invokeTestMethods(TestMethodWorker.java:127)
	at org.testng.internal.TestMethodWorker.run(TestMethodWorker.java:111)
	at org.testng.TestRunner.privateRun(TestRunner.java:767)
	at org.testng.TestRunner.run(TestRunner.java:617)
	at org.testng.SuiteRunner.runTest(SuiteRunner.java:334)
	at org.testng.SuiteRunner.runSequentially(SuiteRunner.java:329)
	at org.testng.SuiteRunner.privateRun(SuiteRunner.java:291)
	at org.testng.SuiteRunner.run(SuiteRunner.java:240)
	at org.testng.SuiteRunnerWorker.runSuite(SuiteRunnerWorker.java:52)
	at org.testng.SuiteRunnerWorker.run(SuiteRunnerWorker.java:86)
	at org.testng.TestNG.runSuitesSequentially(TestNG.java:1198)
	at org.testng.TestNG.runSuitesLocally(TestNG.java:1123)
	at org.testng.TestNG.run(TestNG.java:1031)
	at org.testng.remote.AbstractRemoteTestNG.run(AbstractRemoteTestNG.java:126)
	at org.testng.remote.RemoteTestNG.initAndRun(RemoteTestNG.java:137)
	at org.testng.remote.RemoteTestNG.main(RemoteTestNG.java:58)
]]>
    </failure>
  </testcase> <!-- apiErrorMixCasesPassword -->
  <testcase name="apiErrorBlankContactFirstName" time="0.178" classname="automationFramework.NextWave2RestApi.ApiCustomerPost"/>
  <testcase name="apiErrorInvalidPostalCode" time="0.144" classname="automationFramework.NextWave2RestApi.ApiCustomerPost"/>
  <testcase name="apiErrorSecurityQuestionInvalid" time="0.163" classname="automationFramework.NextWave2RestApi.ApiCustomerPost"/>
  <testcase name="apiErrorBlankPhoneType" time="0.117" classname="automationFramework.NextWave2RestApi.ApiCustomerPost">
    <error type="java.lang.AssertionError" message="expected [contact.phone[0].phoneType] but found [contact.phone[0].type]">
      <![CDATA[java.lang.AssertionError: expected [contact.phone[0].phoneType] but found [contact.phone[0].type]
	at org.testng.Assert.fail(Assert.java:94)
	at org.testng.Assert.failNotEquals(Assert.java:494)
	at org.testng.Assert.assertEquals(Assert.java:123)
	at org.testng.Assert.assertEquals(Assert.java:176)
	at org.testng.Assert.assertEquals(Assert.java:186)
	at automationFramework.NextWave2RestApi.ApiCustomerPost.checkError(ApiCustomerPost.java:1019)
	at automationFramework.NextWave2RestApi.ApiCustomerPost.apiErrorBlankPhoneType(ApiCustomerPost.java:440)
	at sun.reflect.NativeMethodAccessorImpl.invoke0(Native Method)
	at sun.reflect.NativeMethodAccessorImpl.invoke(Unknown Source)
	at sun.reflect.DelegatingMethodAccessorImpl.invoke(Unknown Source)
	at java.lang.reflect.Method.invoke(Unknown Source)
	at org.testng.internal.MethodInvocationHelper.invokeMethod(MethodInvocationHelper.java:80)
	at org.testng.internal.Invoker.invokeMethod(Invoker.java:714)
	at org.testng.internal.Invoker.invokeTestMethod(Invoker.java:901)
	at org.testng.internal.Invoker.invokeTestMethods(Invoker.java:1231)
	at org.testng.internal.TestMethodWorker.invokeTestMethods(TestMethodWorker.java:127)
	at org.testng.internal.TestMethodWorker.run(TestMethodWorker.java:111)
	at org.testng.TestRunner.privateRun(TestRunner.java:767)
	at org.testng.TestRunner.run(TestRunner.java:617)
	at org.testng.SuiteRunner.runTest(SuiteRunner.java:334)
	at org.testng.SuiteRunner.runSequentially(SuiteRunner.java:329)
	at org.testng.SuiteRunner.privateRun(SuiteRunner.java:291)
	at org.testng.SuiteRunner.run(SuiteRunner.java:240)
	at org.testng.SuiteRunnerWorker.runSuite(SuiteRunnerWorker.java:52)
	at org.testng.SuiteRunnerWorker.run(SuiteRunnerWorker.java:86)
	at org.testng.TestNG.runSuitesSequentially(TestNG.java:1198)
	at org.testng.TestNG.runSuitesLocally(TestNG.java:1123)
	at org.testng.TestNG.run(TestNG.java:1031)
	at org.testng.remote.AbstractRemoteTestNG.run(AbstractRemoteTestNG.java:126)
	at org.testng.remote.RemoteTestNG.initAndRun(RemoteTestNG.java:137)
	at org.testng.remote.RemoteTestNG.main(RemoteTestNG.java:58)
]]>
    </error>
  </testcase> <!-- apiErrorBlankPhoneType -->
  <testcase name="apiErrorContainSpecialCharactersPassword" time="0.173" classname="automationFramework.NextWave2RestApi.ApiCustomerPost">
    <failure type="java.lang.NullPointerException">
      <![CDATA[java.lang.NullPointerException
	at automationFramework.NextWave2RestApi.ApiCustomerPost.checkError(ApiCustomerPost.java:1019)
	at automationFramework.NextWave2RestApi.ApiCustomerPost.apiErrorContainSpecialCharactersPassword(ApiCustomerPost.java:763)
	at sun.reflect.NativeMethodAccessorImpl.invoke0(Native Method)
	at sun.reflect.NativeMethodAccessorImpl.invoke(Unknown Source)
	at sun.reflect.DelegatingMethodAccessorImpl.invoke(Unknown Source)
	at java.lang.reflect.Method.invoke(Unknown Source)
	at org.testng.internal.MethodInvocationHelper.invokeMethod(MethodInvocationHelper.java:80)
	at org.testng.internal.Invoker.invokeMethod(Invoker.java:714)
	at org.testng.internal.Invoker.invokeTestMethod(Invoker.java:901)
	at org.testng.internal.Invoker.invokeTestMethods(Invoker.java:1231)
	at org.testng.internal.TestMethodWorker.invokeTestMethods(TestMethodWorker.java:127)
	at org.testng.internal.TestMethodWorker.run(TestMethodWorker.java:111)
	at org.testng.TestRunner.privateRun(TestRunner.java:767)
	at org.testng.TestRunner.run(TestRunner.java:617)
	at org.testng.SuiteRunner.runTest(SuiteRunner.java:334)
	at org.testng.SuiteRunner.runSequentially(SuiteRunner.java:329)
	at org.testng.SuiteRunner.privateRun(SuiteRunner.java:291)
	at org.testng.SuiteRunner.run(SuiteRunner.java:240)
	at org.testng.SuiteRunnerWorker.runSuite(SuiteRunnerWorker.java:52)
	at org.testng.SuiteRunnerWorker.run(SuiteRunnerWorker.java:86)
	at org.testng.TestNG.runSuitesSequentially(TestNG.java:1198)
	at org.testng.TestNG.runSuitesLocally(TestNG.java:1123)
	at org.testng.TestNG.run(TestNG.java:1031)
	at org.testng.remote.AbstractRemoteTestNG.run(AbstractRemoteTestNG.java:126)
	at org.testng.remote.RemoteTestNG.initAndRun(RemoteTestNG.java:137)
	at org.testng.remote.RemoteTestNG.main(RemoteTestNG.java:58)
]]>
    </failure>
  </testcase> <!-- apiErrorContainSpecialCharactersPassword -->
  <testcase name="apiErrorInvalidState" time="0.119" classname="automationFramework.NextWave2RestApi.ApiCustomerPost"/>
  <testcase name="apiErrorBlankPhoneNumber2" time="0.125" classname="automationFramework.NextWave2RestApi.ApiCustomerPost">
    <error type="java.lang.AssertionError" message="expected [contact.phone[1].phoneNumber] but found [contact.phone[1].number]">
      <![CDATA[java.lang.AssertionError: expected [contact.phone[1].phoneNumber] but found [contact.phone[1].number]
	at org.testng.Assert.fail(Assert.java:94)
	at org.testng.Assert.failNotEquals(Assert.java:494)
	at org.testng.Assert.assertEquals(Assert.java:123)
	at org.testng.Assert.assertEquals(Assert.java:176)
	at org.testng.Assert.assertEquals(Assert.java:186)
	at automationFramework.NextWave2RestApi.ApiCustomerPost.checkError(ApiCustomerPost.java:1019)
	at automationFramework.NextWave2RestApi.ApiCustomerPost.apiErrorBlankPhoneNumber2(ApiCustomerPost.java:460)
	at sun.reflect.NativeMethodAccessorImpl.invoke0(Native Method)
	at sun.reflect.NativeMethodAccessorImpl.invoke(Unknown Source)
	at sun.reflect.DelegatingMethodAccessorImpl.invoke(Unknown Source)
	at java.lang.reflect.Method.invoke(Unknown Source)
	at org.testng.internal.MethodInvocationHelper.invokeMethod(MethodInvocationHelper.java:80)
	at org.testng.internal.Invoker.invokeMethod(Invoker.java:714)
	at org.testng.internal.Invoker.invokeTestMethod(Invoker.java:901)
	at org.testng.internal.Invoker.invokeTestMethods(Invoker.java:1231)
	at org.testng.internal.TestMethodWorker.invokeTestMethods(TestMethodWorker.java:127)
	at org.testng.internal.TestMethodWorker.run(TestMethodWorker.java:111)
	at org.testng.TestRunner.privateRun(TestRunner.java:767)
	at org.testng.TestRunner.run(TestRunner.java:617)
	at org.testng.SuiteRunner.runTest(SuiteRunner.java:334)
	at org.testng.SuiteRunner.runSequentially(SuiteRunner.java:329)
	at org.testng.SuiteRunner.privateRun(SuiteRunner.java:291)
	at org.testng.SuiteRunner.run(SuiteRunner.java:240)
	at org.testng.SuiteRunnerWorker.runSuite(SuiteRunnerWorker.java:52)
	at org.testng.SuiteRunnerWorker.run(SuiteRunnerWorker.java:86)
	at org.testng.TestNG.runSuitesSequentially(TestNG.java:1198)
	at org.testng.TestNG.runSuitesLocally(TestNG.java:1123)
	at org.testng.TestNG.run(TestNG.java:1031)
	at org.testng.remote.AbstractRemoteTestNG.run(AbstractRemoteTestNG.java:126)
	at org.testng.remote.RemoteTestNG.initAndRun(RemoteTestNG.java:137)
	at org.testng.remote.RemoteTestNG.main(RemoteTestNG.java:58)
]]>
    </error>
  </testcase> <!-- apiErrorBlankPhoneNumber2 -->
  <testcase name="apiErrorInvalidSuffixId" time="0.133" classname="automationFramework.NextWave2RestApi.ApiCustomerPost"/>
  <testcase name="apiErrorDuplicateUserName" time="0.210" classname="automationFramework.NextWave2RestApi.ApiCustomerPost"/>
  <testcase name="apiErrorMaxLengthUserName" time="0.213" classname="automationFramework.NextWave2RestApi.ApiCustomerPost"/>
  <testcase name="apiErrorContainDictionaryPassword" time="0.222" classname="automationFramework.NextWave2RestApi.ApiCustomerPost">
    <failure type="java.lang.NullPointerException">
      <![CDATA[java.lang.NullPointerException
	at automationFramework.NextWave2RestApi.ApiCustomerPost.checkError(ApiCustomerPost.java:1019)
	at automationFramework.NextWave2RestApi.ApiCustomerPost.apiErrorContainDictionaryPassword(ApiCustomerPost.java:773)
	at sun.reflect.NativeMethodAccessorImpl.invoke0(Native Method)
	at sun.reflect.NativeMethodAccessorImpl.invoke(Unknown Source)
	at sun.reflect.DelegatingMethodAccessorImpl.invoke(Unknown Source)
	at java.lang.reflect.Method.invoke(Unknown Source)
	at org.testng.internal.MethodInvocationHelper.invokeMethod(MethodInvocationHelper.java:80)
	at org.testng.internal.Invoker.invokeMethod(Invoker.java:714)
	at org.testng.internal.Invoker.invokeTestMethod(Invoker.java:901)
	at org.testng.internal.Invoker.invokeTestMethods(Invoker.java:1231)
	at org.testng.internal.TestMethodWorker.invokeTestMethods(TestMethodWorker.java:127)
	at org.testng.internal.TestMethodWorker.run(TestMethodWorker.java:111)
	at org.testng.TestRunner.privateRun(TestRunner.java:767)
	at org.testng.TestRunner.run(TestRunner.java:617)
	at org.testng.SuiteRunner.runTest(SuiteRunner.java:334)
	at org.testng.SuiteRunner.runSequentially(SuiteRunner.java:329)
	at org.testng.SuiteRunner.privateRun(SuiteRunner.java:291)
	at org.testng.SuiteRunner.run(SuiteRunner.java:240)
	at org.testng.SuiteRunnerWorker.runSuite(SuiteRunnerWorker.java:52)
	at org.testng.SuiteRunnerWorker.run(SuiteRunnerWorker.java:86)
	at org.testng.TestNG.runSuitesSequentially(TestNG.java:1198)
	at org.testng.TestNG.runSuitesLocally(TestNG.java:1123)
	at org.testng.TestNG.run(TestNG.java:1031)
	at org.testng.remote.AbstractRemoteTestNG.run(AbstractRemoteTestNG.java:126)
	at org.testng.remote.RemoteTestNG.initAndRun(RemoteTestNG.java:137)
	at org.testng.remote.RemoteTestNG.main(RemoteTestNG.java:58)
]]>
    </failure>
  </testcase> <!-- apiErrorContainDictionaryPassword -->
  <testcase name="apiErrorInvalidCountry" time="0.107" classname="automationFramework.NextWave2RestApi.ApiCustomerPost"/>
  <testcase name="apiErrorBlankAddress" time="1.155" classname="automationFramework.NextWave2RestApi.ApiCustomerPost"/>
  <testcase name="apiErrorMaxLengthPassword" time="0.141" classname="automationFramework.NextWave2RestApi.ApiCustomerPost">
    <failure type="java.lang.NullPointerException">
      <![CDATA[java.lang.NullPointerException
	at automationFramework.NextWave2RestApi.ApiCustomerPost.checkError(ApiCustomerPost.java:1019)
	at automationFramework.NextWave2RestApi.ApiCustomerPost.apiErrorMaxLengthPassword(ApiCustomerPost.java:723)
	at sun.reflect.NativeMethodAccessorImpl.invoke0(Native Method)
	at sun.reflect.NativeMethodAccessorImpl.invoke(Unknown Source)
	at sun.reflect.DelegatingMethodAccessorImpl.invoke(Unknown Source)
	at java.lang.reflect.Method.invoke(Unknown Source)
	at org.testng.internal.MethodInvocationHelper.invokeMethod(MethodInvocationHelper.java:80)
	at org.testng.internal.Invoker.invokeMethod(Invoker.java:714)
	at org.testng.internal.Invoker.invokeTestMethod(Invoker.java:901)
	at org.testng.internal.Invoker.invokeTestMethods(Invoker.java:1231)
	at org.testng.internal.TestMethodWorker.invokeTestMethods(TestMethodWorker.java:127)
	at org.testng.internal.TestMethodWorker.run(TestMethodWorker.java:111)
	at org.testng.TestRunner.privateRun(TestRunner.java:767)
	at org.testng.TestRunner.run(TestRunner.java:617)
	at org.testng.SuiteRunner.runTest(SuiteRunner.java:334)
	at org.testng.SuiteRunner.runSequentially(SuiteRunner.java:329)
	at org.testng.SuiteRunner.privateRun(SuiteRunner.java:291)
	at org.testng.SuiteRunner.run(SuiteRunner.java:240)
	at org.testng.SuiteRunnerWorker.runSuite(SuiteRunnerWorker.java:52)
	at org.testng.SuiteRunnerWorker.run(SuiteRunnerWorker.java:86)
	at org.testng.TestNG.runSuitesSequentially(TestNG.java:1198)
	at org.testng.TestNG.runSuitesLocally(TestNG.java:1123)
	at org.testng.TestNG.run(TestNG.java:1031)
	at org.testng.remote.AbstractRemoteTestNG.run(AbstractRemoteTestNG.java:126)
	at org.testng.remote.RemoteTestNG.initAndRun(RemoteTestNG.java:137)
	at org.testng.remote.RemoteTestNG.main(RemoteTestNG.java:58)
]]>
    </failure>
  </testcase> <!-- apiErrorMaxLengthPassword -->
  <testcase name="apiErrorTooSmallPin" time="0.787" classname="automationFramework.NextWave2RestApi.ApiCustomerPost"/>
  <testcase name="apiErrorInvalidPhoneNumber3" time="0.111" classname="automationFramework.NextWave2RestApi.ApiCustomerPost">
    <error type="java.lang.AssertionError" message="expected [contact.phone[2].phoneNumber] but found [contact.phone[2].number]">
      <![CDATA[java.lang.AssertionError: expected [contact.phone[2].phoneNumber] but found [contact.phone[2].number]
	at org.testng.Assert.fail(Assert.java:94)
	at org.testng.Assert.failNotEquals(Assert.java:494)
	at org.testng.Assert.assertEquals(Assert.java:123)
	at org.testng.Assert.assertEquals(Assert.java:176)
	at org.testng.Assert.assertEquals(Assert.java:186)
	at automationFramework.NextWave2RestApi.ApiCustomerPost.checkError(ApiCustomerPost.java:1019)
	at automationFramework.NextWave2RestApi.ApiCustomerPost.apiErrorInvalidPhoneNumber3(ApiCustomerPost.java:510)
	at sun.reflect.NativeMethodAccessorImpl.invoke0(Native Method)
	at sun.reflect.NativeMethodAccessorImpl.invoke(Unknown Source)
	at sun.reflect.DelegatingMethodAccessorImpl.invoke(Unknown Source)
	at java.lang.reflect.Method.invoke(Unknown Source)
	at org.testng.internal.MethodInvocationHelper.invokeMethod(MethodInvocationHelper.java:80)
	at org.testng.internal.Invoker.invokeMethod(Invoker.java:714)
	at org.testng.internal.Invoker.invokeTestMethod(Invoker.java:901)
	at org.testng.internal.Invoker.invokeTestMethods(Invoker.java:1231)
	at org.testng.internal.TestMethodWorker.invokeTestMethods(TestMethodWorker.java:127)
	at org.testng.internal.TestMethodWorker.run(TestMethodWorker.java:111)
	at org.testng.TestRunner.privateRun(TestRunner.java:767)
	at org.testng.TestRunner.run(TestRunner.java:617)
	at org.testng.SuiteRunner.runTest(SuiteRunner.java:334)
	at org.testng.SuiteRunner.runSequentially(SuiteRunner.java:329)
	at org.testng.SuiteRunner.privateRun(SuiteRunner.java:291)
	at org.testng.SuiteRunner.run(SuiteRunner.java:240)
	at org.testng.SuiteRunnerWorker.runSuite(SuiteRunnerWorker.java:52)
	at org.testng.SuiteRunnerWorker.run(SuiteRunnerWorker.java:86)
	at org.testng.TestNG.runSuitesSequentially(TestNG.java:1198)
	at org.testng.TestNG.runSuitesLocally(TestNG.java:1123)
	at org.testng.TestNG.run(TestNG.java:1031)
	at org.testng.remote.AbstractRemoteTestNG.run(AbstractRemoteTestNG.java:126)
	at org.testng.remote.RemoteTestNG.initAndRun(RemoteTestNG.java:137)
	at org.testng.remote.RemoteTestNG.main(RemoteTestNG.java:58)
]]>
    </error>
  </testcase> <!-- apiErrorInvalidPhoneNumber3 -->
  <testcase name="apiErrorAddressId" time="1.638" classname="automationFramework.NextWave2RestApi.ApiCustomerPost">
    <failure type="java.lang.NullPointerException">
      <![CDATA[java.lang.NullPointerException
	at automationFramework.NextWave2RestApi.ApiCustomerPost.checkError(ApiCustomerPost.java:1019)
	at automationFramework.NextWave2RestApi.ApiCustomerPost.apiErrorAddressId(ApiCustomerPost.java:297)
	at sun.reflect.NativeMethodAccessorImpl.invoke0(Native Method)
	at sun.reflect.NativeMethodAccessorImpl.invoke(Unknown Source)
	at sun.reflect.DelegatingMethodAccessorImpl.invoke(Unknown Source)
	at java.lang.reflect.Method.invoke(Unknown Source)
	at org.testng.internal.MethodInvocationHelper.invokeMethod(MethodInvocationHelper.java:80)
	at org.testng.internal.Invoker.invokeMethod(Invoker.java:714)
	at org.testng.internal.Invoker.invokeTestMethod(Invoker.java:901)
	at org.testng.internal.Invoker.invokeTestMethods(Invoker.java:1231)
	at org.testng.internal.TestMethodWorker.invokeTestMethods(TestMethodWorker.java:127)
	at org.testng.internal.TestMethodWorker.run(TestMethodWorker.java:111)
	at org.testng.TestRunner.privateRun(TestRunner.java:767)
	at org.testng.TestRunner.run(TestRunner.java:617)
	at org.testng.SuiteRunner.runTest(SuiteRunner.java:334)
	at org.testng.SuiteRunner.runSequentially(SuiteRunner.java:329)
	at org.testng.SuiteRunner.privateRun(SuiteRunner.java:291)
	at org.testng.SuiteRunner.run(SuiteRunner.java:240)
	at org.testng.SuiteRunnerWorker.runSuite(SuiteRunnerWorker.java:52)
	at org.testng.SuiteRunnerWorker.run(SuiteRunnerWorker.java:86)
	at org.testng.TestNG.runSuitesSequentially(TestNG.java:1198)
	at org.testng.TestNG.runSuitesLocally(TestNG.java:1123)
	at org.testng.TestNG.run(TestNG.java:1031)
	at org.testng.remote.AbstractRemoteTestNG.run(AbstractRemoteTestNG.java:126)
	at org.testng.remote.RemoteTestNG.initAndRun(RemoteTestNG.java:137)
	at org.testng.remote.RemoteTestNG.main(RemoteTestNG.java:58)
]]>
    </failure>
  </testcase> <!-- apiErrorAddressId -->
  <testcase name="apiErrorInvalidPhoneType3" time="0.154" classname="automationFramework.NextWave2RestApi.ApiCustomerPost">
    <error type="java.lang.AssertionError" message="expected [contact.phone[2].phoneType] but found [contact.phone[2].type]">
      <![CDATA[java.lang.AssertionError: expected [contact.phone[2].phoneType] but found [contact.phone[2].type]
	at org.testng.Assert.fail(Assert.java:94)
	at org.testng.Assert.failNotEquals(Assert.java:494)
	at org.testng.Assert.assertEquals(Assert.java:123)
	at org.testng.Assert.assertEquals(Assert.java:176)
	at org.testng.Assert.assertEquals(Assert.java:186)
	at automationFramework.NextWave2RestApi.ApiCustomerPost.checkError(ApiCustomerPost.java:1019)
	at automationFramework.NextWave2RestApi.ApiCustomerPost.apiErrorInvalidPhoneType3(ApiCustomerPost.java:532)
	at sun.reflect.NativeMethodAccessorImpl.invoke0(Native Method)
	at sun.reflect.NativeMethodAccessorImpl.invoke(Unknown Source)
	at sun.reflect.DelegatingMethodAccessorImpl.invoke(Unknown Source)
	at java.lang.reflect.Method.invoke(Unknown Source)
	at org.testng.internal.MethodInvocationHelper.invokeMethod(MethodInvocationHelper.java:80)
	at org.testng.internal.Invoker.invokeMethod(Invoker.java:714)
	at org.testng.internal.Invoker.invokeTestMethod(Invoker.java:901)
	at org.testng.internal.Invoker.invokeTestMethods(Invoker.java:1231)
	at org.testng.internal.TestMethodWorker.invokeTestMethods(TestMethodWorker.java:127)
	at org.testng.internal.TestMethodWorker.run(TestMethodWorker.java:111)
	at org.testng.TestRunner.privateRun(TestRunner.java:767)
	at org.testng.TestRunner.run(TestRunner.java:617)
	at org.testng.SuiteRunner.runTest(SuiteRunner.java:334)
	at org.testng.SuiteRunner.runSequentially(SuiteRunner.java:329)
	at org.testng.SuiteRunner.privateRun(SuiteRunner.java:291)
	at org.testng.SuiteRunner.run(SuiteRunner.java:240)
	at org.testng.SuiteRunnerWorker.runSuite(SuiteRunnerWorker.java:52)
	at org.testng.SuiteRunnerWorker.run(SuiteRunnerWorker.java:86)
	at org.testng.TestNG.runSuitesSequentially(TestNG.java:1198)
	at org.testng.TestNG.runSuitesLocally(TestNG.java:1123)
	at org.testng.TestNG.run(TestNG.java:1031)
	at org.testng.remote.AbstractRemoteTestNG.run(AbstractRemoteTestNG.java:126)
	at org.testng.remote.RemoteTestNG.initAndRun(RemoteTestNG.java:137)
	at org.testng.remote.RemoteTestNG.main(RemoteTestNG.java:58)
]]>
    </error>
  </testcase> <!-- apiErrorInvalidPhoneType3 -->
  <testcase name="apiPostSuccess" time="0.142" classname="automationFramework.NextWave2RestApi.ApiCustomerPost"/>
  <testcase name="apiErrorMaxLengthContactFirstName" time="0.120" classname="automationFramework.NextWave2RestApi.ApiCustomerPost"/>
  <testcase name="apiErrorSpecialCharactersUserName" time="0.100" classname="automationFramework.NextWave2RestApi.ApiCustomerPost"/>
  <testcase name="apiErrorBlankPhoneType2" time="0.149" classname="automationFramework.NextWave2RestApi.ApiCustomerPost">
    <error type="java.lang.AssertionError" message="expected [contact.phone[1].phoneType] but found [contact.phone[1].type]">
      <![CDATA[java.lang.AssertionError: expected [contact.phone[1].phoneType] but found [contact.phone[1].type]
	at org.testng.Assert.fail(Assert.java:94)
	at org.testng.Assert.failNotEquals(Assert.java:494)
	at org.testng.Assert.assertEquals(Assert.java:123)
	at org.testng.Assert.assertEquals(Assert.java:176)
	at org.testng.Assert.assertEquals(Assert.java:186)
	at automationFramework.NextWave2RestApi.ApiCustomerPost.checkError(ApiCustomerPost.java:1019)
	at automationFramework.NextWave2RestApi.ApiCustomerPost.apiErrorBlankPhoneType2(ApiCustomerPost.java:481)
	at sun.reflect.NativeMethodAccessorImpl.invoke0(Native Method)
	at sun.reflect.NativeMethodAccessorImpl.invoke(Unknown Source)
	at sun.reflect.DelegatingMethodAccessorImpl.invoke(Unknown Source)
	at java.lang.reflect.Method.invoke(Unknown Source)
	at org.testng.internal.MethodInvocationHelper.invokeMethod(MethodInvocationHelper.java:80)
	at org.testng.internal.Invoker.invokeMethod(Invoker.java:714)
	at org.testng.internal.Invoker.invokeTestMethod(Invoker.java:901)
	at org.testng.internal.Invoker.invokeTestMethods(Invoker.java:1231)
	at org.testng.internal.TestMethodWorker.invokeTestMethods(TestMethodWorker.java:127)
	at org.testng.internal.TestMethodWorker.run(TestMethodWorker.java:111)
	at org.testng.TestRunner.privateRun(TestRunner.java:767)
	at org.testng.TestRunner.run(TestRunner.java:617)
	at org.testng.SuiteRunner.runTest(SuiteRunner.java:334)
	at org.testng.SuiteRunner.runSequentially(SuiteRunner.java:329)
	at org.testng.SuiteRunner.privateRun(SuiteRunner.java:291)
	at org.testng.SuiteRunner.run(SuiteRunner.java:240)
	at org.testng.SuiteRunnerWorker.runSuite(SuiteRunnerWorker.java:52)
	at org.testng.SuiteRunnerWorker.run(SuiteRunnerWorker.java:86)
	at org.testng.TestNG.runSuitesSequentially(TestNG.java:1198)
	at org.testng.TestNG.runSuitesLocally(TestNG.java:1123)
	at org.testng.TestNG.run(TestNG.java:1031)
	at org.testng.remote.AbstractRemoteTestNG.run(AbstractRemoteTestNG.java:126)
	at org.testng.remote.RemoteTestNG.initAndRun(RemoteTestNG.java:137)
	at org.testng.remote.RemoteTestNG.main(RemoteTestNG.java:58)
]]>
    </error>
  </testcase> <!-- apiErrorBlankPhoneType2 -->
  <testcase name="apiErrorContainDigitsPassword" time="0.150" classname="automationFramework.NextWave2RestApi.ApiCustomerPost">
    <failure type="java.lang.NullPointerException">
      <![CDATA[java.lang.NullPointerException
	at automationFramework.NextWave2RestApi.ApiCustomerPost.checkError(ApiCustomerPost.java:1019)
	at automationFramework.NextWave2RestApi.ApiCustomerPost.apiErrorContainDigitsPassword(ApiCustomerPost.java:733)
	at sun.reflect.NativeMethodAccessorImpl.invoke0(Native Method)
	at sun.reflect.NativeMethodAccessorImpl.invoke(Unknown Source)
	at sun.reflect.DelegatingMethodAccessorImpl.invoke(Unknown Source)
	at java.lang.reflect.Method.invoke(Unknown Source)
	at org.testng.internal.MethodInvocationHelper.invokeMethod(MethodInvocationHelper.java:80)
	at org.testng.internal.Invoker.invokeMethod(Invoker.java:714)
	at org.testng.internal.Invoker.invokeTestMethod(Invoker.java:901)
	at org.testng.internal.Invoker.invokeTestMethods(Invoker.java:1231)
	at org.testng.internal.TestMethodWorker.invokeTestMethods(TestMethodWorker.java:127)
	at org.testng.internal.TestMethodWorker.run(TestMethodWorker.java:111)
	at org.testng.TestRunner.privateRun(TestRunner.java:767)
	at org.testng.TestRunner.run(TestRunner.java:617)
	at org.testng.SuiteRunner.runTest(SuiteRunner.java:334)
	at org.testng.SuiteRunner.runSequentially(SuiteRunner.java:329)
	at org.testng.SuiteRunner.privateRun(SuiteRunner.java:291)
	at org.testng.SuiteRunner.run(SuiteRunner.java:240)
	at org.testng.SuiteRunnerWorker.runSuite(SuiteRunnerWorker.java:52)
	at org.testng.SuiteRunnerWorker.run(SuiteRunnerWorker.java:86)
	at org.testng.TestNG.runSuitesSequentially(TestNG.java:1198)
	at org.testng.TestNG.runSuitesLocally(TestNG.java:1123)
	at org.testng.TestNG.run(TestNG.java:1031)
	at org.testng.remote.AbstractRemoteTestNG.run(AbstractRemoteTestNG.java:126)
	at org.testng.remote.RemoteTestNG.initAndRun(RemoteTestNG.java:137)
	at org.testng.remote.RemoteTestNG.main(RemoteTestNG.java:58)
]]>
    </failure>
  </testcase> <!-- apiErrorContainDigitsPassword -->
  <testcase name="apiErrorInvalidFormatEmail" time="0.143" classname="automationFramework.NextWave2RestApi.ApiCustomerPost"/>
  <testcase name="apiErrorBlankContactName" time="0.435" classname="automationFramework.NextWave2RestApi.ApiCustomerPost"/>
  <testcase name="apiErrorContainConsecutiveCharacterPin" time="0.158" classname="automationFramework.NextWave2RestApi.ApiCustomerPost">
    <failure type="java.lang.NullPointerException">
      <![CDATA[java.lang.NullPointerException
	at automationFramework.NextWave2RestApi.ApiCustomerPost.checkError(ApiCustomerPost.java:1019)
	at automationFramework.NextWave2RestApi.ApiCustomerPost.apiErrorContainConsecutiveCharacterPin(ApiCustomerPost.java:794)
	at sun.reflect.NativeMethodAccessorImpl.invoke0(Native Method)
	at sun.reflect.NativeMethodAccessorImpl.invoke(Unknown Source)
	at sun.reflect.DelegatingMethodAccessorImpl.invoke(Unknown Source)
	at java.lang.reflect.Method.invoke(Unknown Source)
	at org.testng.internal.MethodInvocationHelper.invokeMethod(MethodInvocationHelper.java:80)
	at org.testng.internal.Invoker.invokeMethod(Invoker.java:714)
	at org.testng.internal.Invoker.invokeTestMethod(Invoker.java:901)
	at org.testng.internal.Invoker.invokeTestMethods(Invoker.java:1231)
	at org.testng.internal.TestMethodWorker.invokeTestMethods(TestMethodWorker.java:127)
	at org.testng.internal.TestMethodWorker.run(TestMethodWorker.java:111)
	at org.testng.TestRunner.privateRun(TestRunner.java:767)
	at org.testng.TestRunner.run(TestRunner.java:617)
	at org.testng.SuiteRunner.runTest(SuiteRunner.java:334)
	at org.testng.SuiteRunner.runSequentially(SuiteRunner.java:329)
	at org.testng.SuiteRunner.privateRun(SuiteRunner.java:291)
	at org.testng.SuiteRunner.run(SuiteRunner.java:240)
	at org.testng.SuiteRunnerWorker.runSuite(SuiteRunnerWorker.java:52)
	at org.testng.SuiteRunnerWorker.run(SuiteRunnerWorker.java:86)
	at org.testng.TestNG.runSuitesSequentially(TestNG.java:1198)
	at org.testng.TestNG.runSuitesLocally(TestNG.java:1123)
	at org.testng.TestNG.run(TestNG.java:1031)
	at org.testng.remote.AbstractRemoteTestNG.run(AbstractRemoteTestNG.java:126)
	at org.testng.remote.RemoteTestNG.initAndRun(RemoteTestNG.java:137)
	at org.testng.remote.RemoteTestNG.main(RemoteTestNG.java:58)
]]>
    </failure>
  </testcase> <!-- apiErrorContainConsecutiveCharacterPin -->
  <testcase name="apiGetSuccess" time="0.127" classname="automationFramework.NextWave2RestApi.ApiCustomerPost"/>
  <testcase name="apiErrorBlankContactType" time="0.154" classname="automationFramework.NextWave2RestApi.ApiCustomerPost"/>
  <testcase name="apiErrorBlankPersonalId" time="0.178" classname="automationFramework.NextWave2RestApi.ApiCustomerPost"/>
  <testcase name="apiErrorMaxLengthContactLastName" time="0.140" classname="automationFramework.NextWave2RestApi.ApiCustomerPost"/>
  <testcase name="apiErrorInvalidPhoneNumber" time="0.114" classname="automationFramework.NextWave2RestApi.ApiCustomerPost">
    <error type="java.lang.AssertionError" message="expected [contact.phone[0].phoneNumber] but found [contact.phone[0].number]">
      <![CDATA[java.lang.AssertionError: expected [contact.phone[0].phoneNumber] but found [contact.phone[0].number]
	at org.testng.Assert.fail(Assert.java:94)
	at org.testng.Assert.failNotEquals(Assert.java:494)
	at org.testng.Assert.assertEquals(Assert.java:123)
	at org.testng.Assert.assertEquals(Assert.java:176)
	at org.testng.Assert.assertEquals(Assert.java:186)
	at automationFramework.NextWave2RestApi.ApiCustomerPost.checkError(ApiCustomerPost.java:1019)
	at automationFramework.NextWave2RestApi.ApiCustomerPost.apiErrorInvalidPhoneNumber(ApiCustomerPost.java:430)
	at sun.reflect.NativeMethodAccessorImpl.invoke0(Native Method)
	at sun.reflect.NativeMethodAccessorImpl.invoke(Unknown Source)
	at sun.reflect.DelegatingMethodAccessorImpl.invoke(Unknown Source)
	at java.lang.reflect.Method.invoke(Unknown Source)
	at org.testng.internal.MethodInvocationHelper.invokeMethod(MethodInvocationHelper.java:80)
	at org.testng.internal.Invoker.invokeMethod(Invoker.java:714)
	at org.testng.internal.Invoker.invokeTestMethod(Invoker.java:901)
	at org.testng.internal.Invoker.invokeTestMethods(Invoker.java:1231)
	at org.testng.internal.TestMethodWorker.invokeTestMethods(TestMethodWorker.java:127)
	at org.testng.internal.TestMethodWorker.run(TestMethodWorker.java:111)
	at org.testng.TestRunner.privateRun(TestRunner.java:767)
	at org.testng.TestRunner.run(TestRunner.java:617)
	at org.testng.SuiteRunner.runTest(SuiteRunner.java:334)
	at org.testng.SuiteRunner.runSequentially(SuiteRunner.java:329)
	at org.testng.SuiteRunner.privateRun(SuiteRunner.java:291)
	at org.testng.SuiteRunner.run(SuiteRunner.java:240)
	at org.testng.SuiteRunnerWorker.runSuite(SuiteRunnerWorker.java:52)
	at org.testng.SuiteRunnerWorker.run(SuiteRunnerWorker.java:86)
	at org.testng.TestNG.runSuitesSequentially(TestNG.java:1198)
	at org.testng.TestNG.runSuitesLocally(TestNG.java:1123)
	at org.testng.TestNG.run(TestNG.java:1031)
	at org.testng.remote.AbstractRemoteTestNG.run(AbstractRemoteTestNG.java:126)
	at org.testng.remote.RemoteTestNG.initAndRun(RemoteTestNG.java:137)
	at org.testng.remote.RemoteTestNG.main(RemoteTestNG.java:58)
]]>
    </error>
  </testcase> <!-- apiErrorInvalidPhoneNumber -->
  <testcase name="apiErrorContainUsernamePin" time="0.112" classname="automationFramework.NextWave2RestApi.ApiCustomerPost"/>
  <testcase name="apiErrorSpecialCharactersEmail" time="0.106" classname="automationFramework.NextWave2RestApi.ApiCustomerPost"/>
  <testcase name="apiErrorInvalidPhoneType2" time="0.118" classname="automationFramework.NextWave2RestApi.ApiCustomerPost">
    <error type="java.lang.AssertionError" message="expected [contact.phone[1].phoneType] but found [contact.phone[1].type]">
      <![CDATA[java.lang.AssertionError: expected [contact.phone[1].phoneType] but found [contact.phone[1].type]
	at org.testng.Assert.fail(Assert.java:94)
	at org.testng.Assert.failNotEquals(Assert.java:494)
	at org.testng.Assert.assertEquals(Assert.java:123)
	at org.testng.Assert.assertEquals(Assert.java:176)
	at org.testng.Assert.assertEquals(Assert.java:186)
	at automationFramework.NextWave2RestApi.ApiCustomerPost.checkError(ApiCustomerPost.java:1019)
	at automationFramework.NextWave2RestApi.ApiCustomerPost.apiErrorInvalidPhoneType2(ApiCustomerPost.java:491)
	at sun.reflect.NativeMethodAccessorImpl.invoke0(Native Method)
	at sun.reflect.NativeMethodAccessorImpl.invoke(Unknown Source)
	at sun.reflect.DelegatingMethodAccessorImpl.invoke(Unknown Source)
	at java.lang.reflect.Method.invoke(Unknown Source)
	at org.testng.internal.MethodInvocationHelper.invokeMethod(MethodInvocationHelper.java:80)
	at org.testng.internal.Invoker.invokeMethod(Invoker.java:714)
	at org.testng.internal.Invoker.invokeTestMethod(Invoker.java:901)
	at org.testng.internal.Invoker.invokeTestMethods(Invoker.java:1231)
	at org.testng.internal.TestMethodWorker.invokeTestMethods(TestMethodWorker.java:127)
	at org.testng.internal.TestMethodWorker.run(TestMethodWorker.java:111)
	at org.testng.TestRunner.privateRun(TestRunner.java:767)
	at org.testng.TestRunner.run(TestRunner.java:617)
	at org.testng.SuiteRunner.runTest(SuiteRunner.java:334)
	at org.testng.SuiteRunner.runSequentially(SuiteRunner.java:329)
	at org.testng.SuiteRunner.privateRun(SuiteRunner.java:291)
	at org.testng.SuiteRunner.run(SuiteRunner.java:240)
	at org.testng.SuiteRunnerWorker.runSuite(SuiteRunnerWorker.java:52)
	at org.testng.SuiteRunnerWorker.run(SuiteRunnerWorker.java:86)
	at org.testng.TestNG.runSuitesSequentially(TestNG.java:1198)
	at org.testng.TestNG.runSuitesLocally(TestNG.java:1123)
	at org.testng.TestNG.run(TestNG.java:1031)
	at org.testng.remote.AbstractRemoteTestNG.run(AbstractRemoteTestNG.java:126)
	at org.testng.remote.RemoteTestNG.initAndRun(RemoteTestNG.java:137)
	at org.testng.remote.RemoteTestNG.main(RemoteTestNG.java:58)
]]>
    </error>
  </testcase> <!-- apiErrorInvalidPhoneType2 -->
  <testcase name="apiErrorMustContainLettersPassword" time="0.148" classname="automationFramework.NextWave2RestApi.ApiCustomerPost"/>
  <testcase name="apiErrorBlankState" time="0.153" classname="automationFramework.NextWave2RestApi.ApiCustomerPost"/>
  <testcase name="apiErrorBlankCity" time="0.140" classname="automationFramework.NextWave2RestApi.ApiCustomerPost"/>
  <testcase name="apiErrorBlankPassword" time="0.118" classname="automationFramework.NextWave2RestApi.ApiCustomerPost"/>
  <testcase name="apiErrorBlankContact" time="0.145" classname="automationFramework.NextWave2RestApi.ApiCustomerPost"/>
  <testcase name="apiErrorMaximumLengthEmail" time="0.120" classname="automationFramework.NextWave2RestApi.ApiCustomerPost"/>
  <testcase name="apiErrorBlankCustomerType" time="0.127" classname="automationFramework.NextWave2RestApi.ApiCustomerPost"/>
  <testcase name="apiErrorBlankPostalCode" time="0.111" classname="automationFramework.NextWave2RestApi.ApiCustomerPost"/>
  <testcase name="apiErrorMaxLengthAddress" time="0.133" classname="automationFramework.NextWave2RestApi.ApiCustomerPost"/>
  <testcase name="apiErrorSecurityQuestionBlank" time="0.133" classname="automationFramework.NextWave2RestApi.ApiCustomerPost"/>
  <testcase name="apiErrorMinLengthPassword" time="0.150" classname="automationFramework.NextWave2RestApi.ApiCustomerPost"/>
  <testcase name="apiErrorMaxLengthContactMiddleName" time="0.120" classname="automationFramework.NextWave2RestApi.ApiCustomerPost"/>
  <testcase name="apiErrorNonNumericPin" time="0.158" classname="automationFramework.NextWave2RestApi.ApiCustomerPost"/>
  <testcase name="apiErrorSecurityAnswerBlank" time="0.111" classname="automationFramework.NextWave2RestApi.ApiCustomerPost"/>
  <testcase name="apiErrorBlankCountry" time="0.115" classname="automationFramework.NextWave2RestApi.ApiCustomerPost"/>
  <testcase name="apiErrorBlankEmail" time="0.179" classname="automationFramework.NextWave2RestApi.ApiCustomerPost"/>
  <testcase name="apiErrorSecurityAnswerMaxLength" time="1.368" classname="automationFramework.NextWave2RestApi.ApiCustomerPost"/>
  <testcase name="apiErrorInvalidPhoneNumber2" time="0.148" classname="automationFramework.NextWave2RestApi.ApiCustomerPost">
    <error type="java.lang.AssertionError" message="expected [contact.phone[1].phoneNumber] but found [contact.phone[1].number]">
      <![CDATA[java.lang.AssertionError: expected [contact.phone[1].phoneNumber] but found [contact.phone[1].number]
	at org.testng.Assert.fail(Assert.java:94)
	at org.testng.Assert.failNotEquals(Assert.java:494)
	at org.testng.Assert.assertEquals(Assert.java:123)
	at org.testng.Assert.assertEquals(Assert.java:176)
	at org.testng.Assert.assertEquals(Assert.java:186)
	at automationFramework.NextWave2RestApi.ApiCustomerPost.checkError(ApiCustomerPost.java:1019)
	at automationFramework.NextWave2RestApi.ApiCustomerPost.apiErrorInvalidPhoneNumber2(ApiCustomerPost.java:470)
	at sun.reflect.NativeMethodAccessorImpl.invoke0(Native Method)
	at sun.reflect.NativeMethodAccessorImpl.invoke(Unknown Source)
	at sun.reflect.DelegatingMethodAccessorImpl.invoke(Unknown Source)
	at java.lang.reflect.Method.invoke(Unknown Source)
	at org.testng.internal.MethodInvocationHelper.invokeMethod(MethodInvocationHelper.java:80)
	at org.testng.internal.Invoker.invokeMethod(Invoker.java:714)
	at org.testng.internal.Invoker.invokeTestMethod(Invoker.java:901)
	at org.testng.internal.Invoker.invokeTestMethods(Invoker.java:1231)
	at org.testng.internal.TestMethodWorker.invokeTestMethods(TestMethodWorker.java:127)
	at org.testng.internal.TestMethodWorker.run(TestMethodWorker.java:111)
	at org.testng.TestRunner.privateRun(TestRunner.java:767)
	at org.testng.TestRunner.run(TestRunner.java:617)
	at org.testng.SuiteRunner.runTest(SuiteRunner.java:334)
	at org.testng.SuiteRunner.runSequentially(SuiteRunner.java:329)
	at org.testng.SuiteRunner.privateRun(SuiteRunner.java:291)
	at org.testng.SuiteRunner.run(SuiteRunner.java:240)
	at org.testng.SuiteRunnerWorker.runSuite(SuiteRunnerWorker.java:52)
	at org.testng.SuiteRunnerWorker.run(SuiteRunnerWorker.java:86)
	at org.testng.TestNG.runSuitesSequentially(TestNG.java:1198)
	at org.testng.TestNG.runSuitesLocally(TestNG.java:1123)
	at org.testng.TestNG.run(TestNG.java:1031)
	at org.testng.remote.AbstractRemoteTestNG.run(AbstractRemoteTestNG.java:126)
	at org.testng.remote.RemoteTestNG.initAndRun(RemoteTestNG.java:137)
	at org.testng.remote.RemoteTestNG.main(RemoteTestNG.java:58)
]]>
    </error>
  </testcase> <!-- apiErrorInvalidPhoneNumber2 -->
  <testcase name="apiErrorInvalidContactType" time="0.136" classname="automationFramework.NextWave2RestApi.ApiCustomerPost"/>
</testsuite> <!-- automationFramework.NextWave2RestApi.ApiCustomerPost -->
